<mujoco model="robocrane_mjx">

  <compiler
  autolimits="true"
  angle="radian"
  />

<option
  timestep="0.001"
  gravity="0 0 -9.81"
  integrator="implicitfast"
  cone="elliptic"
  jacobian="sparse"
  solver="Newton"
  iterations="4"
  ls_iterations="10"
  />

  <statistic meansize="0.03" extent="0.3" center="0.3 0 0" />
  <default>
    <default class="/" />
    <default class="lab/" />
    <default class="lab/iiwa/" />
    <default class="lab/iiwa/cardan_joint/">
      <default class="lab/iiwa/cardan_joint/visual">
        <geom type="mesh" contype="0" conaffinity="0" group="2" />
      </default>
      <default class="lab/iiwa/cardan_joint/collision">
        <geom type="mesh" group="3" />
      </default>
    </default>
    <default class="lab/iiwa/cardan_joint/ur_gripper/2f85">
      <mesh scale="0.001 0.001 0.001" />
      <joint axis="1 0 0" />
      <general biastype="affine" />
      <default class="lab/iiwa/cardan_joint/ur_gripper/visual2">
        <geom type="mesh" contype="0" conaffinity="0" group="2" material="lab/iiwa/cardan_joint/ur_gripper/gray2" />
      </default>
      <default class="lab/iiwa/cardan_joint/ur_gripper/driver">
        <joint solreflimit="0.005 1" solimplimit="0.95 0.99 0.001" range="0 0.8" armature="0.005" damping="0.1" />
      </default>
      <default class="lab/iiwa/cardan_joint/ur_gripper/follower">
        <joint pos="0 -0.018 0.0065" solreflimit="0.005 1" solimplimit="0.95 0.99 0.001" range="-0.8727 0.8727" />
      </default>
      <default class="lab/iiwa/cardan_joint/ur_gripper/spring_link">
        <joint stiffness="0.05" range="-0.2967 0.8" springref="2.62" damping="0.00125" />
      </default>
      <default class="lab/iiwa/cardan_joint/ur_gripper/coupler">
        <joint solreflimit="0.005 1" solimplimit="0.95 0.99 0.001" range="-1.57 0" />
      </default>
      <default class="lab/iiwa/cardan_joint/ur_gripper/collision2">
        <geom type="box" condim="3" group="3" rgba="1 0.4235 0.03922 1" />
        <default class="lab/iiwa/cardan_joint/ur_gripper/pad_box1">
          <geom type="box" priority="1" size="0.011 0.004 0.009375" rgba="0.55 0.55 0.55 1" friction="0.7" mass="0" solref="0.004 1" solimp="0.95 0.99 0.001" pos="0 -0.0026 0.02813" />
        </default>
        <default class="lab/iiwa/cardan_joint/ur_gripper/pad_box2">
          <geom type="box" priority="1" size="0.011 0.004 0.009375" rgba="0.45 0.45 0.45 1" friction="0.6" mass="0" solref="0.004 1" solimp="0.95 0.99 0.001" pos="0 -0.0026 0.009375" />
        </default>
      </default>
    </default>
    <default class="wall/" />
    <default class="block_green/" />
    <default class="block_orange/" />
    <default class="block_blue/" />
  </default>
  <asset>
    <texture name="lab//unnamed_texture_0" type="skybox" builtin="gradient" rgb1="0.6 0.8 1" rgb2="0.2 0.2 0.2" width="512" height="3072" />
    <texture name="lab/groundplane" type="2d" builtin="checker" rgb1="0.5 0.7 0.9" rgb2="0.3 0.5 0.7" mark="edge" markrgb="0.9 0.9 0.9" width="300" height="300" />
    <material name="lab/groundplane" class="lab/" texture="lab/groundplane" texrepeat="5 5" texuniform="true" reflectance="0.4" />
    <mesh maxhullvert="10" name="lab/iiwa/link_0" class="lab/iiwa/" file="base_link-5923539fbd7857ea716ff1bc3ef3f05fb44fefdd.stl" />
    <mesh maxhullvert="10" name="lab/iiwa/link_1" class="lab/iiwa/" file="link_1-ac6245160be1a43d652c2a2c3b73a58d1dfa90e4.stl" />
    <mesh maxhullvert="10" name="lab/iiwa/link_2" class="lab/iiwa/" file="link_2-825b1e76e8e7c70ae4c8d112f62701a01555dcf5.stl" />
    <mesh maxhullvert="10" name="lab/iiwa/link_3" class="lab/iiwa/" file="link_3-b55302ba767376e20501905d1e5ea3ae6b70998d.stl" />
    <mesh maxhullvert="10" name="lab/iiwa/link_4" class="lab/iiwa/" file="link_4-05ccd5ecc00b0d36b59bc264f7cec382d4c4122b.stl" />
    <mesh maxhullvert="10" name="lab/iiwa/link_5" class="lab/iiwa/" file="link_5-fcf25b48909184c134560cfa93731b85bf4698c9.stl" />
    <mesh maxhullvert="10" name="lab/iiwa/link_6" class="lab/iiwa/" file="link_6-955785181a16fa937663f7db1c496e9605b820a9.stl" />
    <mesh maxhullvert="10" name="lab/iiwa/link_7" class="lab/iiwa/" file="link_7-85a5c154edcbf21b01a9031cc0a7c9861a4e0fed.stl" />
    <mesh maxhullvert="10" name="lab/iiwa/cardan_joint/cj_cam_mount" class="lab/iiwa/cardan_joint/" file="cj_top_V4_coll-6f3e36287b54bdd5ad2518d59e4cc865785780c3.obj" />
    <mesh maxhullvert="10" name="lab/iiwa/cardan_joint/cj_middle" class="lab/iiwa/cardan_joint/" file="cj_middle-1309231b4c0a493c2b65609bbb64275813619889.obj" />
    <mesh maxhullvert="10" name="lab/iiwa/cardan_joint/cj_bot" class="lab/iiwa/cardan_joint/" file="cj_asm_half-947726d4ba6162bd80d70f31db90d4ae33ecd56c.obj" />
    <mesh maxhullvert="10" name="lab/iiwa/cardan_joint/cj_cam_mount_vis" class="lab/iiwa/cardan_joint/" file="cj_top_V4-76978c996657efe89708b43b67fb00f5f31b4bc6.obj" />
    <mesh maxhullvert="10" name="lab/iiwa/cardan_joint/cj_middle_vis" class="lab/iiwa/cardan_joint/" file="cj_middle_vis-e08f93e997c48b5995634064a579731fca49cfe9.obj" />
    <mesh maxhullvert="10" name="lab/iiwa/cardan_joint/cj_bot_vis" class="lab/iiwa/cardan_joint/" file="cj_asm_half_vis-10e9d2e22a7610ed98d9ae3b58b68799d0da53a0.obj" />
    <mesh maxhullvert="10" name="lab/iiwa/cardan_joint/ur_gripper/base_mount" class="lab/iiwa/cardan_joint/ur_gripper/2f85" file="base_mount-22e57178defe77afb6bdd333bfae16607f1eb3dd.stl" />
    <mesh maxhullvert="10" name="lab/iiwa/cardan_joint/ur_gripper/base" class="lab/iiwa/cardan_joint/ur_gripper/2f85" file="base-e5dacbcc3971bfdb549ff8c7d38ea873ca7f2933.stl" />
    <mesh maxhullvert="10" name="lab/iiwa/cardan_joint/ur_gripper/driver" class="lab/iiwa/cardan_joint/ur_gripper/2f85" file="driver-97efa43184c575b31ff1f3980641896f51492762.stl" />
    <mesh maxhullvert="10" name="lab/iiwa/cardan_joint/ur_gripper/coupler" class="lab/iiwa/cardan_joint/ur_gripper/2f85" file="coupler-0a4240dc94992944cca6ec9e270ff1658fa86c55.stl" />
    <mesh maxhullvert="10" name="lab/iiwa/cardan_joint/ur_gripper/follower" class="lab/iiwa/cardan_joint/ur_gripper/2f85" file="follower-39e4b8048f1395ee38cb45b37b5fec0e6f2aaec9.stl" />
    <mesh maxhullvert="10" name="lab/iiwa/cardan_joint/ur_gripper/pad" class="lab/iiwa/cardan_joint/ur_gripper/2f85" file="pad-e6a633b2c81740b1f783ec4c6e695c8cc570f09d.stl" />
    <mesh maxhullvert="10" name="lab/iiwa/cardan_joint/ur_gripper/silicone_pad" class="lab/iiwa/cardan_joint/ur_gripper/2f85" file="silicone_pad-c284384f3ca6dcdc24d6188a5d1a2d4c42c412ac.stl" />
    <mesh maxhullvert="10" name="lab/iiwa/cardan_joint/ur_gripper/spring_link" class="lab/iiwa/cardan_joint/ur_gripper/2f85" file="spring_link-8f50234325193b84e9f86b7a63a24560a389c9bf.stl" />
    <material name="lab/iiwa/cardan_joint/ur_gripper/black2" class="lab/iiwa/cardan_joint/ur_gripper/2f85" rgba="0.149 0.149 0.149 1" />
    <material name="lab/iiwa/cardan_joint/ur_gripper/wood2" class="lab/iiwa/cardan_joint/ur_gripper/2f85" rgba="0.56 0.37 0.29 1" />
    <material name="lab/iiwa/cardan_joint/ur_gripper/gray2" class="lab/iiwa/cardan_joint/ur_gripper/2f85" rgba="0.4 0.4 0.4 1" />
    <material name="wall/wood" class="wall/" specular="0.1" shininess="0.2" reflectance="0.05" rgba="0.55 0.27 0.07 1" />
    <material name="wall/aluminum" class="wall/" specular="0.8" shininess="0.9" reflectance="0.6" rgba="0.8 0.8 0.8 1" />
  </asset>
  <worldbody>
    <body name="ground" mocap="false" pos="0 0 0">
      <site name="ground_site_attach" class="/" />
      <body name="lab/">
        <light name="lab//unnamed_light_0" class="lab/" directional="true" pos="0 0 1.5" dir="0 0 -1" />
        <geom name="lab/floor" class="lab/" type="plane" size="0 0 0.05" material="lab/groundplane" />
        <site name="lab/ground_attach" class="lab/" group="0" rgba="1 0 0 1" size="0.01" pos="0 0 0" />
        <body pos="0 0 0" name="lab/iiwa/">
          <body name="lab/iiwa/base" pos="0 0 0">
            <camera name="lab/iiwa/robotview" class="lab/iiwa/" mode="fixed" pos="1 0 0.4" quat="0.653 0.271 0.271 0.653" />
            <inertial pos="0 0 0" mass="0" diaginertia="0 0 0" />
            <geom name="lab/iiwa//unnamed_geom_0" class="lab/iiwa/" type="mesh" contype="0" conaffinity="0" group="1" rgba="0.4 0.4 0.4 1" density="0" mesh="lab/iiwa/link_0" />
            <geom name="lab/iiwa/col_sockel" class="lab/iiwa/" type="sphere" contype="0" conaffinity="0" group="3" size="0.12" rgba="1 0 0 1" density="0" pos="-0.01 0 0.1" />
            <body name="lab/iiwa/iiwa_link_1" pos="0 0 0.1575">
              <inertial pos="0 -0.01439 0.1025" quat="1 0 0 0" mass="6.495" diaginertia="0.06908 0.07111 0.02006" />
              <joint name="lab/iiwa/joint_1" class="lab/iiwa/" pos="0 0 0" axis="0 0 1" limited="true" range="-2.967 2.967" />
              <geom name="lab/iiwa//unnamed_geom_2" class="lab/iiwa/" type="mesh" contype="0" conaffinity="0" group="1" rgba="0.4 0.4 0.4 1" density="0" pos="0 0 -0.005" mesh="lab/iiwa/link_1" />
              <geom name="lab/iiwa/col_joint1" class="lab/iiwa/" type="capsule" contype="1" conaffinity="1" group="3" size="0.075" rgba="0.4 0.4 0.4 1" density="0" fromto="0 0 0 0 -0.05 0.2025" quat="0 0 0 1" />
              <body name="lab/iiwa/iiwa_link_2" pos="0 0 0.2025" quat="0 0 0.7071 0.7071">
                <inertial pos="1.2e-05 0.06472 0.004804" quat="1 0 0 0" mass="8.807" diaginertia="0.08247 0.01641 0.08735" />
                <joint name="lab/iiwa/joint_2" class="lab/iiwa/" pos="0 0 0" axis="0 0 1" limited="true" range="-2.094 2.094" />
                <geom name="lab/iiwa//unnamed_geom_4" class="lab/iiwa/" type="mesh" contype="0" conaffinity="0" group="1" rgba="1 0.4235 0.03922 1" density="0" pos="0 0 -0.013" quat="0 0 0 1" mesh="lab/iiwa/link_2" />
                <geom name="lab/iiwa/col_joint2" class="lab/iiwa/" type="capsule" contype="1" conaffinity="1" group="3" size="0.075" rgba="1 0.4235 0.03922 1" density="0" fromto="0 0 0.0513 0 0.2375 0" quat="0 0 0 1" />
                <body name="lab/iiwa/iiwa_link_3" pos="0 0.2375 0" quat="0 0 0.7071 0.7071">
                  <inertial pos="-0.000208 0.01601 0.08728" quat="1 0 0 0" mass="2.8" diaginertia="0.02302 0.02287 0.04545" />
                  <joint name="lab/iiwa/joint_3" class="lab/iiwa/" pos="0 0 0" axis="0 0 1" limited="true" range="-2.967 2.967" />
                  <geom name="lab/iiwa//unnamed_geom_6" class="lab/iiwa/" type="mesh" contype="0" conaffinity="0" group="1" rgba="0.4 0.4 0.4 1" density="0" pos="0 0 -0.005" mesh="lab/iiwa/link_3" />
                  <geom name="lab/iiwa/col_joint3" class="lab/iiwa/" type="capsule" contype="1" conaffinity="1" group="3" size="0.07" rgba="0.4 0.4 0.4 1" density="0" fromto="0 0 0 0 0.05 0.1825" quat="0 0 0 1" />
                  <body name="lab/iiwa/iiwa_link_4" pos="0 0 0.1825" quat="0.7071 0.7071 0 0">
                    <inertial pos="-0.000203 0.09864 0.01148" quat="1 0 0 0" mass="5.283" diaginertia="0.04728 0.009647 0.04665" />
                    <joint name="lab/iiwa/joint_4" class="lab/iiwa/" pos="0 0 0" axis="0 0 1" limited="true" range="-2.094 2.094" />
                    <geom name="lab/iiwa//unnamed_geom_8" class="lab/iiwa/" type="mesh" contype="0" conaffinity="0" group="1" rgba="1 0.4235 0.03922 1" density="0" pos="0 0 -0.011" mesh="lab/iiwa/link_4" />
                    <geom name="lab/iiwa/col_joint4" class="lab/iiwa/" type="capsule" contype="1" conaffinity="1" group="3" size="0.07" rgba="1 0.4235 0.03922 1" density="0" fromto="0 0 0.04 0 0.2175 0" quat="0 0 0 1" />
                    <body name="lab/iiwa/iiwa_link_5" pos="0 0.2175 0" quat="0 0 0.7071 0.7071">
                      <inertial pos="5.7e-05 0.01447 0.06294" mass="1.889" diaginertia="0.01384 0.01169 0.005719" />
                      <joint name="lab/iiwa/joint_5" class="lab/iiwa/" pos="0 0 0" axis="0 0 1" limited="true" range="-2.967 2.967" />
                      <geom name="lab/iiwa//unnamed_geom_10" class="lab/iiwa/" type="mesh" contype="0" conaffinity="0" group="1" rgba="0.4 0.4 0.4 1" density="0" pos="0 0 -0.005" quat="0 0 0 1" mesh="lab/iiwa/link_5" />
                      <geom name="lab/iiwa/col_joint5" class="lab/iiwa/" type="capsule" contype="1" conaffinity="1" group="3" size="0.07" rgba="0.4 0.4 0.4 1" density="0" fromto="0 0 0 0 0.03 0.1825" quat="0 0 0 1" />
                      <body name="lab/iiwa/iiwa_link_6" pos="0 0 0.1825" quat="0.7071 0.7071 0 0">
                        <inertial pos="0.000363 0.01698 -0.01973" quat="1 0 0 0" mass="2.32" diaginertia="0.007328 0.004776 0.006068" />
                        <joint name="lab/iiwa/joint_6" class="lab/iiwa/" pos="0 0 0" axis="0 0 1" limited="true" range="-2.094 2.094" />
                        <geom name="lab/iiwa//unnamed_geom_12" class="lab/iiwa/" type="mesh" contype="0" conaffinity="0" group="1" rgba="1 0.4235 0.03922 1" density="0" pos="0 0 -0.061" quat="0 0 0 1" mesh="lab/iiwa/link_6" />
                        <geom name="lab/iiwa/col_joint67" class="lab/iiwa/" type="capsule" contype="1" conaffinity="1" group="3" size="0.06" rgba="1 0.4235 0.03922 1" density="0" fromto="0 0 0 0 0.081 0" quat="0 0 0 1" />
                        <body name="lab/iiwa/iiwa_link_7" pos="0 0.081 0" quat="0 0 0.7071 0.7071">
                          <inertial pos="0.001904 -9.3e-05 0.01886" quat="1 0 0 0" mass="0.863" diaginertia="0.000884 0.000888 0.001105" />
                          <joint name="lab/iiwa/joint_7" class="lab/iiwa/" pos="0 0 0" axis="0 0 1" limited="true" range="-3.054 3.054" />
                          <geom name="lab/iiwa//unnamed_geom_14" class="lab/iiwa/" type="mesh" contype="0" conaffinity="0" group="1" rgba="0.4 0.4 0.4 1" density="0" mesh="lab/iiwa/link_7" />
                          <site name="lab/iiwa/gripper_attachment" class="lab/iiwa/" group="0" rgba="1 0 0 1" size="0.01" pos="0 0 0.071" />
                          <body pos="0 0 0.071" name="lab/iiwa/cardan_joint/">
                            <body name="lab/iiwa/cardan_joint/cj_top" pos="0 0 0" quat="0.5 0.5 -0.5 -0.5">
                              <inertial pos="0.0135 -0 0.02238" quat="1 0 0 0" mass="0.5" diaginertia="0.000124 0.000378 0.000425" />
                              <geom name="lab/iiwa/cardan_joint//unnamed_geom_0" class="lab/iiwa/cardan_joint/visual" contype="0" conaffinity="0" group="2" quat="0.7071 0 0 0.7071" mesh="lab/iiwa/cardan_joint/cj_cam_mount_vis" />
                              <geom name="lab/iiwa/cardan_joint//unnamed_geom_1" class="lab/iiwa/cardan_joint/collision" contype="0" quat="0.7071 0 0 0.7071" mesh="lab/iiwa/cardan_joint/cj_cam_mount" />
                              <site name="lab/iiwa/cardan_joint/imu1_site" class="lab/iiwa/cardan_joint/" type="sphere" rgba="1 0 0 1" size="0.004" pos="-0.0138 0.02 0.01" quat="0.5 0.5 -0.5 0.5" />
                              <camera name="lab/iiwa/cardan_joint/eye_in_hand" class="lab/iiwa/cardan_joint/" mode="fixed" fovy="75" pos="-0.17 0.04 0" quat="0.6272 0.6272 0.3265 0.3265" />
                              <site name="lab/iiwa/cardan_joint/camera_site" class="lab/iiwa/cardan_joint/" type="sphere" rgba="1 0 0 1" size="0.004" pos="-0.17 0.04 0" quat="0.6272 0.6272 0.3265 0.3265" />
                              <body name="lab/iiwa/cardan_joint/cj_middle" pos="0 0.048 0" quat="0.7071 -0.7071 0 0">
                                <inertial pos="0 0 0" quat="1 0 0 0" mass="0.016" diaginertia="1e-06 1e-06 1e-06" />
                                <joint name="lab/iiwa/cardan_joint/joint_cj1" class="lab/iiwa/cardan_joint/" pos="0 0 0" axis="-1 0 0" limited="true" range="-1 1" damping="0.005" />
                                <geom name="lab/iiwa/cardan_joint//unnamed_geom_2" class="lab/iiwa/cardan_joint/visual" contype="0" conaffinity="0" group="2" quat="0.7071 0.7071 0 0" mesh="lab/iiwa/cardan_joint/cj_middle_vis" />
                                <geom name="lab/iiwa/cardan_joint//unnamed_geom_3" class="lab/iiwa/cardan_joint/collision" contype="0" conaffinity="0" quat="0.7071 0.7071 0 0" mesh="lab/iiwa/cardan_joint/cj_middle" />
                                <body name="lab/iiwa/cardan_joint/cj_bot" pos="0 0 0.028" quat="0.7071 0 0 -0.7071">
                                  <inertial pos="0 0 0.05" quat="1 0 0 0" mass="1" diaginertia="0.0008 0.0008 0.001" />
                                  <joint name="lab/iiwa/cardan_joint/joint_cj2" class="lab/iiwa/cardan_joint/" pos="0 0 -0.028" axis="-1 0 0" limited="true" range="-1 1" damping="0.005" />
                                  <geom name="lab/iiwa/cardan_joint//unnamed_geom_4" class="lab/iiwa/cardan_joint/visual" contype="0" conaffinity="0" group="2" quat="0 1 0 0" mesh="lab/iiwa/cardan_joint/cj_bot_vis" />
                                  <geom name="lab/iiwa/cardan_joint//unnamed_geom_5" class="lab/iiwa/cardan_joint/collision" contype="0" conaffinity="0" quat="0 1 0 0" mesh="lab/iiwa/cardan_joint/cj_bot" />
                                  <site name="lab/iiwa/cardan_joint/imu2_site" class="lab/iiwa/cardan_joint/" type="sphere" rgba="0 1 0 1" size="0.002" pos="0.0138 0.0124 0" quat="0.7071 0 0 -0.7071" />
                                  <site name="lab/iiwa/cardan_joint/tool_attach" class="lab/iiwa/cardan_joint/" type="sphere" rgba="0 0 1 1" size="0.004" pos="0 0 0.01" quat="0.707 0 0 0.707" />
                                  <body pos="0 0 0.01" quat="0.707 0 0 0.707" name="lab/iiwa/cardan_joint/ur_gripper/">
                                    <body name="lab/iiwa/cardan_joint/ur_gripper/base_mount" childclass="lab/iiwa/cardan_joint/ur_gripper/2f85" pos="0 0 0">
                                      <inertial pos="0 0 0" quat="1 0 0 0" mass="0.0001" diaginertia="1e-06 1e-06 1e-06" />
                                      <geom name="lab/iiwa/cardan_joint/ur_gripper//unnamed_geom_0" class="lab/iiwa/cardan_joint/ur_gripper/visual2" material="lab/iiwa/cardan_joint/ur_gripper/black2" mesh="lab/iiwa/cardan_joint/ur_gripper/base_mount" />
                                      <!-- <geom name="lab/iiwa/cardan_joint/ur_gripper/col_mount" type="cylinder" contype="1" conaffinity="1" group="3" size="0.04 0.0225" rgba="1 0.4235 0.03922 1" pos="0 0 0.016" /> -->
                                      <body name="lab/iiwa/cardan_joint/ur_gripper/base" pos="0 0 0.0038">
                                        <body name="lab/iiwa/cardan_joint/ur_gripper/gripping_point" pos="0 0 0.13">
                                          <site name="lab/iiwa/cardan_joint/ur_gripper/gripping_point" pos="0 0 0" />
                                        </body>
                                        <inertial pos="0 -2.704e-05 0.03547" quat="1 -0.001528 0 0" mass="0.7774" diaginertia="0.0002603 0.0002254 0.0001527" />
                                        <geom name="lab/iiwa/cardan_joint/ur_gripper//unnamed_geom_2" class="lab/iiwa/cardan_joint/ur_gripper/visual2" material="lab/iiwa/cardan_joint/ur_gripper/black2" mesh="lab/iiwa/cardan_joint/ur_gripper/base" />
                                        <geom name="lab/iiwa/cardan_joint/ur_gripper/col_base" type="box" contype="1" conaffinity="1" group="3" size="0.0125 0.03 0.05" rgba="1 0.4235 0.03922 1" pos="0 0 0.038" />
                                        <site name="lab/iiwa/cardan_joint/ur_gripper/pinch" type="sphere" group="8" material="lab/iiwa/cardan_joint/ur_gripper/wood2" size="0.005" pos="0 0 0.145" />
                                        <body name="lab/iiwa/cardan_joint/ur_gripper/right_driver" pos="0 0.0306 0.0549">
                                          <inertial pos="2.969e-12 0.01775 0.001073" quat="0.6813 0.732 0 0" mass="0.008996" diaginertia="1.724e-06 1.609e-06 3.22e-07" />
                                          <!-- <joint name="lab/iiwa/cardan_joint/ur_gripper/right_driver_joint" class="lab/iiwa/cardan_joint/ur_gripper/driver" /> -->
                                          <geom name="lab/iiwa/cardan_joint/ur_gripper//unnamed_geom_4" class="lab/iiwa/cardan_joint/ur_gripper/visual2" material="lab/iiwa/cardan_joint/ur_gripper/gray2" mesh="lab/iiwa/cardan_joint/ur_gripper/driver" />
                                          <body name="lab/iiwa/cardan_joint/ur_gripper/right_coupler" pos="0 0.0315 -0.0041">
                                            <inertial pos="0 0.003012 0.02322" quat="0.7056 -0.04559 0.04559 0.7056" mass="0.0141" diaginertia="4.162e-06 3.522e-06 8.881e-07" />
                                            <!-- <joint name="lab/iiwa/cardan_joint/ur_gripper/right_coupler_joint" class="lab/iiwa/cardan_joint/ur_gripper/coupler" /> -->
                                            <geom name="lab/iiwa/cardan_joint/ur_gripper//unnamed_geom_5" class="lab/iiwa/cardan_joint/ur_gripper/visual2" material="lab/iiwa/cardan_joint/ur_gripper/black2" mesh="lab/iiwa/cardan_joint/ur_gripper/coupler" />
                                            <geom name="lab/iiwa/cardan_joint/ur_gripper/col_right_coupler" type="box" contype="1" conaffinity="1" group="3" size="0.005139 0.01275 0.02689" rgba="1 0 0 1" pos="0 0.003012 0.02322" quat="0.7056 -0.04559 0.04559 0.7056" />
                                          </body>
                                        </body>
                                        <body name="lab/iiwa/cardan_joint/ur_gripper/right_spring_link" pos="0 0.0132 0.0609">
                                          <inertial pos="-8.65e-09 0.01816 0.02127" quat="0.6634 -0.2447 0.2447 0.6634" mass="0.02216" diaginertia="8.969e-06 6.717e-06 2.639e-06" />
                                          <!-- <joint name="lab/iiwa/cardan_joint/ur_gripper/right_spring_link_joint" class="lab/iiwa/cardan_joint/ur_gripper/spring_link" /> -->
                                          <geom name="lab/iiwa/cardan_joint/ur_gripper//unnamed_geom_7" class="lab/iiwa/cardan_joint/ur_gripper/visual2" material="lab/iiwa/cardan_joint/ur_gripper/black2" mesh="lab/iiwa/cardan_joint/ur_gripper/spring_link" />
                                          <body name="lab/iiwa/cardan_joint/ur_gripper/right_follower" pos="0 0.055 0.0375">
                                            <inertial pos="0 -0.01105 0.01248" quat="1 0.1664 0 0" mass="0.01252" diaginertia="2.674e-06 2.456e-06 6.02e-07" />
                                            <!-- <joint name="lab/iiwa/cardan_joint/ur_gripper/right_follower_joint" class="lab/iiwa/cardan_joint/ur_gripper/follower" /> -->
                                            <geom name="lab/iiwa/cardan_joint/ur_gripper//unnamed_geom_8" class="lab/iiwa/cardan_joint/ur_gripper/visual2" material="lab/iiwa/cardan_joint/ur_gripper/black2" mesh="lab/iiwa/cardan_joint/ur_gripper/follower" />
                                            <body name="lab/iiwa/cardan_joint/ur_gripper/right_pad" pos="0 -0.0189 0.01352">
                                              <geom name="lab/iiwa/cardan_joint/ur_gripper/right_pad1" class="lab/iiwa/cardan_joint/ur_gripper/pad_box1" contype="1" conaffinity="1" />
                                              <geom name="lab/iiwa/cardan_joint/ur_gripper/right_pad2" class="lab/iiwa/cardan_joint/ur_gripper/pad_box2" />
                                              <inertial pos="0 -0.0025 0.0185" quat="0.7071 0 0 0.7071" mass="0.0035" diaginertia="4.74e-07 3.646e-07 1.24e-07" />
                                              <geom name="lab/iiwa/cardan_joint/ur_gripper//unnamed_geom_11" class="lab/iiwa/cardan_joint/ur_gripper/visual2" mesh="lab/iiwa/cardan_joint/ur_gripper/pad" />
                                              <body name="lab/iiwa/cardan_joint/ur_gripper/right_silicone_pad">
                                                <geom name="lab/iiwa/cardan_joint/ur_gripper//unnamed_geom_12" class="lab/iiwa/cardan_joint/ur_gripper/visual2" material="lab/iiwa/cardan_joint/ur_gripper/black2" mesh="lab/iiwa/cardan_joint/ur_gripper/silicone_pad" />
                                              </body>
                                            </body>
                                          </body>
                                        </body>
                                        <body name="lab/iiwa/cardan_joint/ur_gripper/left_driver" pos="0 -0.0306 0.0549" quat="0 0 0 1">
                                          <inertial pos="0 0.01775 0.001073" quat="0.6813 0.732 0 0" mass="0.008996" diaginertia="1.724e-06 1.609e-06 3.22e-07" />
                                          <!-- <joint name="lab/iiwa/cardan_joint/ur_gripper/left_driver_joint" class="lab/iiwa/cardan_joint/ur_gripper/driver" /> -->
                                          <geom name="lab/iiwa/cardan_joint/ur_gripper//unnamed_geom_13" class="lab/iiwa/cardan_joint/ur_gripper/visual2" material="lab/iiwa/cardan_joint/ur_gripper/gray2" mesh="lab/iiwa/cardan_joint/ur_gripper/driver" />
                                          <body name="lab/iiwa/cardan_joint/ur_gripper/left_coupler" pos="0 0.0315 -0.0041">
                                            <inertial pos="0 0.003012 0.02322" quat="0.7056 -0.04559 0.04559 0.7056" mass="0.0141" diaginertia="4.162e-06 3.522e-06 8.881e-07" />
                                            <!-- <joint name="lab/iiwa/cardan_joint/ur_gripper/left_coupler_joint" class="lab/iiwa/cardan_joint/ur_gripper/coupler" /> -->
                                            <geom name="lab/iiwa/cardan_joint/ur_gripper//unnamed_geom_14" class="lab/iiwa/cardan_joint/ur_gripper/visual2" material="lab/iiwa/cardan_joint/ur_gripper/black2" mesh="lab/iiwa/cardan_joint/ur_gripper/coupler" />
                                            <geom name="lab/iiwa/cardan_joint/ur_gripper/col_left_coupler" type="box" contype="1" conaffinity="1" group="3" size="0.005139 0.01275 0.02689" rgba="1 0 0 1" pos="0 0.003012 0.02322" quat="0.7056 -0.04559 0.04559 0.7056" />
                                          </body>
                                        </body>
                                        <body name="lab/iiwa/cardan_joint/ur_gripper/left_spring_link" pos="0 -0.0132 0.0609" quat="0 0 0 1">
                                          <inertial pos="-8.65e-09 0.01816 0.02127" quat="0.6634 -0.2447 0.2447 0.6634" mass="0.02216" diaginertia="8.969e-06 6.717e-06 2.639e-06" />
                                          <!-- <joint name="lab/iiwa/cardan_joint/ur_gripper/left_spring_link_joint" class="lab/iiwa/cardan_joint/ur_gripper/spring_link" /> -->
                                          <geom name="lab/iiwa/cardan_joint/ur_gripper//unnamed_geom_16" class="lab/iiwa/cardan_joint/ur_gripper/visual2" material="lab/iiwa/cardan_joint/ur_gripper/black2" mesh="lab/iiwa/cardan_joint/ur_gripper/spring_link" />
                                          <body name="lab/iiwa/cardan_joint/ur_gripper/left_follower" pos="0 0.055 0.0375">
                                            <inertial pos="0 -0.01105 0.01248" quat="1 0.1664 0 0" mass="0.01252" diaginertia="2.674e-06 2.456e-06 6.02e-07" />
                                            <!-- <joint name="lab/iiwa/cardan_joint/ur_gripper/left_follower_joint" class="lab/iiwa/cardan_joint/ur_gripper/follower" /> -->
                                            <geom name="lab/iiwa/cardan_joint/ur_gripper//unnamed_geom_17" class="lab/iiwa/cardan_joint/ur_gripper/visual2" material="lab/iiwa/cardan_joint/ur_gripper/black2" mesh="lab/iiwa/cardan_joint/ur_gripper/follower" />
                                            <body name="lab/iiwa/cardan_joint/ur_gripper/left_pad" pos="0 -0.0189 0.01352">
                                              <geom name="lab/iiwa/cardan_joint/ur_gripper/left_pad1" class="lab/iiwa/cardan_joint/ur_gripper/pad_box1" contype="1" conaffinity="1" />
                                              <geom name="lab/iiwa/cardan_joint/ur_gripper/left_pad2" class="lab/iiwa/cardan_joint/ur_gripper/pad_box2" />
                                              <inertial pos="0 -0.0025 0.0185" quat="1 0 0 1" mass="0.0035" diaginertia="4.74e-07 3.646e-07 1.24e-07" />
                                              <geom name="lab/iiwa/cardan_joint/ur_gripper//unnamed_geom_20" class="lab/iiwa/cardan_joint/ur_gripper/visual2" mesh="lab/iiwa/cardan_joint/ur_gripper/pad" />
                                              <body name="lab/iiwa/cardan_joint/ur_gripper/left_silicone_pad">
                                                <geom name="lab/iiwa/cardan_joint/ur_gripper//unnamed_geom_21" class="lab/iiwa/cardan_joint/ur_gripper/visual2" material="lab/iiwa/cardan_joint/ur_gripper/black2" mesh="lab/iiwa/cardan_joint/ur_gripper/silicone_pad" />
                                              </body>
                                            </body>
                                          </body>
                                        </body>
                                      </body>
                                    </body>
                                  </body>
                                </body>
                              </body>
                            </body>
                          </body>
                        </body>
                      </body>
                    </body>
                  </body>
                </body>
              </body>
            </body>
          </body>
        </body>
      </body>
    </body>

  </worldbody>
  <contact>
    <exclude name="lab/iiwa/cardan_joint/ur_gripper//unnamed_contact_0" body1="lab/iiwa/cardan_joint/ur_gripper/base" body2="lab/iiwa/cardan_joint/ur_gripper/left_driver" />
    <exclude name="lab/iiwa/cardan_joint/ur_gripper//unnamed_contact_1" body1="lab/iiwa/cardan_joint/ur_gripper/base" body2="lab/iiwa/cardan_joint/ur_gripper/right_driver" />
    <exclude name="lab/iiwa/cardan_joint/ur_gripper//unnamed_contact_2" body1="lab/iiwa/cardan_joint/ur_gripper/base" body2="lab/iiwa/cardan_joint/ur_gripper/left_spring_link" />
    <exclude name="lab/iiwa/cardan_joint/ur_gripper//unnamed_contact_3" body1="lab/iiwa/cardan_joint/ur_gripper/base" body2="lab/iiwa/cardan_joint/ur_gripper/right_spring_link" />
    <exclude name="lab/iiwa/cardan_joint/ur_gripper//unnamed_contact_4" body1="lab/iiwa/cardan_joint/ur_gripper/right_coupler" body2="lab/iiwa/cardan_joint/ur_gripper/right_follower" />
    <exclude name="lab/iiwa/cardan_joint/ur_gripper//unnamed_contact_5" body1="lab/iiwa/cardan_joint/ur_gripper/left_coupler" body2="lab/iiwa/cardan_joint/ur_gripper/left_follower" />
  </contact>
  <!-- <equality>
    <connect name="lab/iiwa/cardan_joint/ur_gripper//unnamed_equality_0" class="lab/iiwa/cardan_joint/ur_gripper/2f85" solref="0.005 1" solimp="0.95 0.99 0.001" body1="lab/iiwa/cardan_joint/ur_gripper/right_follower" body2="lab/iiwa/cardan_joint/ur_gripper/right_coupler" anchor="0 0 0" />
    <connect name="lab/iiwa/cardan_joint/ur_gripper//unnamed_equality_1" class="lab/iiwa/cardan_joint/ur_gripper/2f85" solref="0.005 1" solimp="0.95 0.99 0.001" body1="lab/iiwa/cardan_joint/ur_gripper/left_follower" body2="lab/iiwa/cardan_joint/ur_gripper/left_coupler" anchor="0 0 0" />
    <joint name="lab/iiwa/cardan_joint/ur_gripper//unnamed_equality_2" class="lab/iiwa/cardan_joint/ur_gripper/2f85" solref="0.005 1" solimp="0.95 0.99 0.001" joint1="lab/iiwa/cardan_joint/ur_gripper/right_driver_joint" joint2="lab/iiwa/cardan_joint/ur_gripper/left_driver_joint" polycoef="0 1 0 0 0" />
  </equality> -->
  <!-- <tendon>
    <fixed name="lab/iiwa/cardan_joint/ur_gripper/split" class="lab/iiwa/cardan_joint/ur_gripper/2f85">
      <joint joint="lab/iiwa/cardan_joint/ur_gripper/right_driver_joint" coef="0.5" />
      <joint joint="lab/iiwa/cardan_joint/ur_gripper/left_driver_joint" coef="0.5" />
    </fixed>
  </tendon> -->

  <actuator>
    <motor name="lab/iiwa/torq_j1" class="lab/iiwa/" ctrllimited="true" ctrlrange="-176 176" joint="lab/iiwa/joint_1" />
    <motor name="lab/iiwa/torq_j2" class="lab/iiwa/" ctrllimited="true" ctrlrange="-176 176" joint="lab/iiwa/joint_2" />
    <motor name="lab/iiwa/torq_j3" class="lab/iiwa/" ctrllimited="true" ctrlrange="-110 110" joint="lab/iiwa/joint_3" />
    <motor name="lab/iiwa/torq_j4" class="lab/iiwa/" ctrllimited="true" ctrlrange="-110 110" joint="lab/iiwa/joint_4" />
    <motor name="lab/iiwa/torq_j5" class="lab/iiwa/" ctrllimited="true" ctrlrange="-110 110" joint="lab/iiwa/joint_5" />
    <motor name="lab/iiwa/torq_j6" class="lab/iiwa/" ctrllimited="true" ctrlrange="-40 40" joint="lab/iiwa/joint_6" />
    <motor name="lab/iiwa/torq_j7" class="lab/iiwa/" ctrllimited="true" ctrlrange="-40 40" joint="lab/iiwa/joint_7" />
    <!-- <general name="lab/iiwa/cardan_joint/ur_gripper/fingers_actuator" class="lab/iiwa/cardan_joint/ur_gripper/2f85" ctrlrange="0 255" forcerange="-5 5" tendon="lab/iiwa/cardan_joint/ur_gripper/split" gainprm="0.3137 0 0" biasprm="0 -100 -10" /> -->
  </actuator>

  <!-- <actuator>
    <intvelocity name="lab/iiwa/torq_j1" class="lab/iiwa/" actrange="-2.967 2.967" joint="lab/iiwa/joint_1" kv="50" kp="1000"/>
    <intvelocity name="lab/iiwa/torq_j2" class="lab/iiwa/" actrange="-2.967 2.967" joint="lab/iiwa/joint_2" kv="50" kp="1000"/>
    <intvelocity name="lab/iiwa/torq_j3" class="lab/iiwa/" actrange="-1.92 1.92" joint="lab/iiwa/joint_3" kv="50" kp="1000"/>
    <intvelocity name="lab/iiwa/torq_j4" class="lab/iiwa/" actrange="-1.92 1.92" joint="lab/iiwa/joint_4" kv="50" kp="1000"/>
    <intvelocity name="lab/iiwa/torq_j5" class="lab/iiwa/" actrange="-1.92 1.92" joint="lab/iiwa/joint_5" kv="50" kp="1000"/>
    <intvelocity name="lab/iiwa/torq_j6" class="lab/iiwa/" actrange="-0.69 0.69" joint="lab/iiwa/joint_6" kv="50" kp="1000"/>
    <intvelocity name="lab/iiwa/torq_j7" class="lab/iiwa/" actrange="-0.69 0.69" joint="lab/iiwa/joint_7" kv="50" kp="1000"/>
  </actuator> -->

  <sensor>
    <accelerometer name="lab/iiwa/cardan_joint/acc1" site="lab/iiwa/cardan_joint/imu1_site" />
    <gyro name="lab/iiwa/cardan_joint/gyro1" site="lab/iiwa/cardan_joint/imu1_site" />
    <accelerometer name="lab/iiwa/cardan_joint/acc2" site="lab/iiwa/cardan_joint/imu2_site" />
    <gyro name="lab/iiwa/cardan_joint/gyro2" site="lab/iiwa/cardan_joint/imu2_site" />
  </sensor>

  <contact>
  <exclude body1="lab/iiwa/cardan_joint/cj_top"
           body2="lab/iiwa/cardan_joint/cj_bot" />
  </contact>
</mujoco>
